<?xml version="1.0" ?>
<robot name="3LINKARM" xmlns:xacro="http://www.ros.org/wiki/xacro">

<xacro:include filename="/mnt/c/Users/drk22/OneDrive/Rutgers MAE Fall 2025/Spacecraft Sloshing Problem Research/manipulator arm sim/3LINKARM_description/urdf/materials.xacro" />
<xacro:include filename="/mnt/c/Users/drk22/OneDrive/Rutgers MAE Fall 2025/Spacecraft Sloshing Problem Research/manipulator arm sim/3LINKARM_description/urdf/3LINKARM.trans" />
<xacro:include filename="/mnt/c/Users/drk22/OneDrive/Rutgers MAE Fall 2025/Spacecraft Sloshing Problem Research/manipulator arm sim/3LINKARM_description/urdf/3LINKARM.gazebo" />
<link name="base_link">
  <inertial>
    <origin xyz="0.014408270090721952 1.5153473686554524e-11 3.3601592816093436e-12" rpy="0 0 0"/>
    <mass value="5.321860575806323"/>
    <inertia ixx="0.062191" iyy="0.074922" izz="0.030348" ixy="-0.0" iyz="0.0" ixz="-0.0"/>
  </inertial>
  <visual>
    <origin xyz="0 0 0" rpy="0 0 0"/>
    <geometry>
      <mesh filename="file:///mnt/c/Users/drk22/OneDrive/Rutgers MAE Fall 2025/Spacecraft Sloshing Problem Research/manipulator arm sim/3LINKARM_description/meshes/base_link.stl" scale="0.001 0.001 0.001"/>
    </geometry>
    <material name="silver"/>
  </visual>
  <collision>
    <origin xyz="0 0 0" rpy="0 0 0"/>
    <geometry>
      <mesh filename="file:///mnt/c/Users/drk22/OneDrive/Rutgers MAE Fall 2025/Spacecraft Sloshing Problem Research/manipulator arm sim/3LINKARM_description/meshes/base_link.stl" scale="0.001 0.001 0.001"/>
    </geometry>
  </collision>
</link>

<link name="link_0_1">
  <inertial>
    <origin xyz="0.04343313287902885 0.014999999994012265 0.01575069015570966" rpy="0 0 0"/>
    <mass value="0.12631006738224843"/>
    <inertia ixx="3.7e-05" iyy="0.000106" izz="9.9e-05" ixy="-0.0" iyz="-0.0" ixz="-2.6e-05"/>
  </inertial>
  <visual>
    <origin xyz="-0.1125 0.015 -0.0" rpy="0 0 0"/>
    <geometry>
      <mesh filename="file:///mnt/c/Users/drk22/OneDrive/Rutgers MAE Fall 2025/Spacecraft Sloshing Problem Research/manipulator arm sim/3LINKARM_description/meshes/link_0_1.stl" scale="0.001 0.001 0.001"/>
    </geometry>
    <material name="silver"/>
  </visual>
  <collision>
    <origin xyz="-0.1125 0.015 -0.0" rpy="0 0 0"/>
    <geometry>
      <mesh filename="file:///mnt/c/Users/drk22/OneDrive/Rutgers MAE Fall 2025/Spacecraft Sloshing Problem Research/manipulator arm sim/3LINKARM_description/meshes/link_0_1.stl" scale="0.001 0.001 0.001"/>
    </geometry>
  </collision>
</link>

<link name="link_1_1">
  <inertial>
    <origin xyz="0.08468099993010422 -0.015000000000000013 -0.023425122115934678" rpy="0 0 0"/>
    <mass value="0.2548873378723056"/>
    <inertia ixx="1.8e-05" iyy="0.000434" izz="0.000435" ixy="0.0" iyz="-0.0" ixz="-0.0"/>
  </inertial>
  <visual>
    <origin xyz="-0.172316 -0.015 -0.050026" rpy="0 0 0"/>
    <geometry>
      <mesh filename="file:///mnt/c/Users/drk22/OneDrive/Rutgers MAE Fall 2025/Spacecraft Sloshing Problem Research/manipulator arm sim/3LINKARM_description/meshes/link_1_1.stl" scale="0.001 0.001 0.001"/>
    </geometry>
    <material name="silver"/>
  </visual>
  <collision>
    <origin xyz="-0.172316 -0.015 -0.050026" rpy="0 0 0"/>
    <geometry>
      <mesh filename="file:///mnt/c/Users/drk22/OneDrive/Rutgers MAE Fall 2025/Spacecraft Sloshing Problem Research/manipulator arm sim/3LINKARM_description/meshes/link_1_1.stl" scale="0.001 0.001 0.001"/>
    </geometry>
  </collision>
</link>

<link name="link_2_1">
  <inertial>
    <origin xyz="0.04338026294313668 0.01499999999261418 -0.01997655921950387" rpy="0 0 0"/>
    <mass value="0.10240058379302179"/>
    <inertia ixx="2.8e-05" iyy="7.6e-05" izz="7.5e-05" ixy="0.0" iyz="0.0" ixz="-8e-06"/>
  </inertial>
  <visual>
    <origin xyz="-0.311658 0.015 -0.053079" rpy="0 0 0"/>
    <geometry>
      <mesh filename="file:///mnt/c/Users/drk22/OneDrive/Rutgers MAE Fall 2025/Spacecraft Sloshing Problem Research/manipulator arm sim/3LINKARM_description/meshes/link_2_1.stl" scale="0.001 0.001 0.001"/>
    </geometry>
    <material name="silver"/>
  </visual>
  <collision>
    <origin xyz="-0.311658 0.015 -0.053079" rpy="0 0 0"/>
    <geometry>
      <mesh filename="file:///mnt/c/Users/drk22/OneDrive/Rutgers MAE Fall 2025/Spacecraft Sloshing Problem Research/manipulator arm sim/3LINKARM_description/meshes/link_2_1.stl" scale="0.001 0.001 0.001"/>
    </geometry>
  </collision>
</link>

<joint name="joint_0" type="revolute">
  <origin xyz="0.1125 -0.015 0.0" rpy="0 0 0"/>
  <parent link="base_link"/>
  <child link="link_0_1"/>
  <axis xyz="0.0 -1.0 0.0"/>
  <limit upper="0.349066" lower="-0.349066" effort="100" velocity="100"/>
</joint>

<joint name="joint_1" type="revolute">
  <origin xyz="0.059816 0.03 0.050026" rpy="0 0 0"/>
  <parent link="link_0_1"/>
  <child link="link_1_1"/>
  <axis xyz="0.0 1.0 -0.0"/>
  <limit upper="0.349066" lower="-0.349066" effort="100" velocity="100"/>
</joint>

<joint name="joint_2" type="revolute">
  <origin xyz="0.139342 -0.03 0.003053" rpy="0 0 0"/>
  <parent link="link_1_1"/>
  <child link="link_2_1"/>
  <axis xyz="-0.0 -1.0 0.0"/>
  <limit upper="0.349066" lower="-0.349066" effort="100" velocity="100"/>
</joint>

</robot>
