<?xml version="1.0" ?>
<!-- =================================================================================== -->
<!-- |    This document was autogenerated by xacro from 3LINKARM.xacro                 | -->
<!-- |    EDITING THIS FILE BY HAND IS NOT RECOMMENDED                                 | -->
<!-- =================================================================================== -->
<robot name="3LINKARM">
  <material name="silver">
    <color rgba="0.700 0.700 0.700 1.000"/>
  </material>
  <transmission name="joint_0_tran">
    <type>transmission_interface/SimpleTransmission</type>
    <joint name="joint_0">
      <hardwareInterface>hardware_interface/EffortJointInterface</hardwareInterface>
    </joint>
    <actuator name="joint_0_actr">
      <hardwareInterface>hardware_interface/EffortJointInterface</hardwareInterface>
      <mechanicalReduction>1</mechanicalReduction>
    </actuator>
  </transmission>
  <transmission name="joint_1_tran">
    <type>transmission_interface/SimpleTransmission</type>
    <joint name="joint_1">
      <hardwareInterface>hardware_interface/EffortJointInterface</hardwareInterface>
    </joint>
    <actuator name="joint_1_actr">
      <hardwareInterface>hardware_interface/EffortJointInterface</hardwareInterface>
      <mechanicalReduction>1</mechanicalReduction>
    </actuator>
  </transmission>
  <transmission name="joint_2_tran">
    <type>transmission_interface/SimpleTransmission</type>
    <joint name="joint_2">
      <hardwareInterface>hardware_interface/EffortJointInterface</hardwareInterface>
    </joint>
    <actuator name="joint_2_actr">
      <hardwareInterface>hardware_interface/EffortJointInterface</hardwareInterface>
      <mechanicalReduction>1</mechanicalReduction>
    </actuator>
  </transmission>
  <gazebo>
    <plugin filename="libgazebo_ros_control.so" name="control"/>
  </gazebo>
  <gazebo reference="base_link">
    <material>Gazebo/Silver</material>
    <mu1>0.2</mu1>
    <mu2>0.2</mu2>
    <self_collide>true</self_collide>
    <gravity>true</gravity>
  </gazebo>
  <gazebo reference="link_0_1">
    <material>Gazebo/Silver</material>
    <mu1>0.2</mu1>
    <mu2>0.2</mu2>
    <self_collide>true</self_collide>
  </gazebo>
  <gazebo reference="link_1_1">
    <material>Gazebo/Silver</material>
    <mu1>0.2</mu1>
    <mu2>0.2</mu2>
    <self_collide>true</self_collide>
  </gazebo>
  <gazebo reference="link_2_1">
    <material>Gazebo/Silver</material>
    <mu1>0.2</mu1>
    <mu2>0.2</mu2>
    <self_collide>true</self_collide>
  </gazebo>
  <link name="base_link">
    <inertial>
      <origin rpy="0 0 0" xyz="0.014408270090721952 1.5153473686554524e-11 3.3601592816093436e-12"/>
      <mass value="5.321860575806323"/>
      <inertia ixx="0.062191" ixy="-0.0" ixz="-0.0" iyy="0.074922" iyz="0.0" izz="0.030348"/>
    </inertial>
    <visual>
      <origin rpy="0 0 0" xyz="0 0 0"/>
      <geometry>
        <mesh filename="file:///mnt/c/Users/drk22/OneDrive/Rutgers MAE Fall 2025/Spacecraft Sloshing Problem Research/manipulator arm sim/3LINKARM_description/meshes/base_link.stl" scale="0.001 0.001 0.001"/>
      </geometry>
      <material name="silver"/>
    </visual>
    <collision>
      <origin rpy="0 0 0" xyz="0 0 0"/>
      <geometry>
        <mesh filename="file:///mnt/c/Users/drk22/OneDrive/Rutgers MAE Fall 2025/Spacecraft Sloshing Problem Research/manipulator arm sim/3LINKARM_description/meshes/base_link.stl" scale="0.001 0.001 0.001"/>
      </geometry>
    </collision>
  </link>
  <link name="link_0_1">
    <inertial>
      <origin rpy="0 0 0" xyz="0.04343313287902885 0.014999999994012265 0.01575069015570966"/>
      <mass value="0.12631006738224843"/>
      <inertia ixx="3.7e-05" ixy="-0.0" ixz="-2.6e-05" iyy="0.000106" iyz="-0.0" izz="9.9e-05"/>
    </inertial>
    <visual>
      <origin rpy="0 0 0" xyz="-0.1125 0.015 -0.0"/>
      <geometry>
        <mesh filename="file:///mnt/c/Users/drk22/OneDrive/Rutgers MAE Fall 2025/Spacecraft Sloshing Problem Research/manipulator arm sim/3LINKARM_description/meshes/link_0_1.stl" scale="0.001 0.001 0.001"/>
      </geometry>
      <material name="silver"/>
    </visual>
    <collision>
      <origin rpy="0 0 0" xyz="-0.1125 0.015 -0.0"/>
      <geometry>
        <mesh filename="file:///mnt/c/Users/drk22/OneDrive/Rutgers MAE Fall 2025/Spacecraft Sloshing Problem Research/manipulator arm sim/3LINKARM_description/meshes/link_0_1.stl" scale="0.001 0.001 0.001"/>
      </geometry>
    </collision>
  </link>
  <link name="link_1_1">
    <inertial>
      <origin rpy="0 0 0" xyz="0.08468099993010422 -0.015000000000000013 -0.023425122115934678"/>
      <mass value="0.2548873378723056"/>
      <inertia ixx="1.8e-05" ixy="0.0" ixz="-0.0" iyy="0.000434" iyz="-0.0" izz="0.000435"/>
    </inertial>
    <visual>
      <origin rpy="0 0 0" xyz="-0.172316 -0.015 -0.050026"/>
      <geometry>
        <mesh filename="file:///mnt/c/Users/drk22/OneDrive/Rutgers MAE Fall 2025/Spacecraft Sloshing Problem Research/manipulator arm sim/3LINKARM_description/meshes/link_1_1.stl" scale="0.001 0.001 0.001"/>
      </geometry>
      <material name="silver"/>
    </visual>
    <collision>
      <origin rpy="0 0 0" xyz="-0.172316 -0.015 -0.050026"/>
      <geometry>
        <mesh filename="file:///mnt/c/Users/drk22/OneDrive/Rutgers MAE Fall 2025/Spacecraft Sloshing Problem Research/manipulator arm sim/3LINKARM_description/meshes/link_1_1.stl" scale="0.001 0.001 0.001"/>
      </geometry>
    </collision>
  </link>
  <link name="link_2_1">
    <inertial>
      <origin rpy="0 0 0" xyz="0.04338026294313668 0.01499999999261418 -0.01997655921950387"/>
      <mass value="0.10240058379302179"/>
      <inertia ixx="2.8e-05" ixy="0.0" ixz="-8e-06" iyy="7.6e-05" iyz="0.0" izz="7.5e-05"/>
    </inertial>
    <visual>
      <origin rpy="0 0 0" xyz="-0.311658 0.015 -0.053079"/>
      <geometry>
        <mesh filename="file:///mnt/c/Users/drk22/OneDrive/Rutgers MAE Fall 2025/Spacecraft Sloshing Problem Research/manipulator arm sim/3LINKARM_description/meshes/link_2_1.stl" scale="0.001 0.001 0.001"/>
      </geometry>
      <material name="silver"/>
    </visual>
    <collision>
      <origin rpy="0 0 0" xyz="-0.311658 0.015 -0.053079"/>
      <geometry>
        <mesh filename="file:///mnt/c/Users/drk22/OneDrive/Rutgers MAE Fall 2025/Spacecraft Sloshing Problem Research/manipulator arm sim/3LINKARM_description/meshes/link_2_1.stl" scale="0.001 0.001 0.001"/>
      </geometry>
    </collision>
  </link>
  <joint name="joint_0" type="revolute">
    <origin rpy="0 0 0" xyz="0.1125 -0.015 0.0"/>
    <parent link="base_link"/>
    <child link="link_0_1"/>
    <axis xyz="0.0 -1.0 0.0"/>
    <limit effort="100" lower="-0.349066" upper="0.349066" velocity="100"/>
  </joint>
  <joint name="joint_1" type="revolute">
    <origin rpy="0 0 0" xyz="0.059816 0.03 0.050026"/>
    <parent link="link_0_1"/>
    <child link="link_1_1"/>
    <axis xyz="0.0 1.0 -0.0"/>
    <limit effort="100" lower="-0.349066" upper="0.349066" velocity="100"/>
  </joint>
  <joint name="joint_2" type="revolute">
    <origin rpy="0 0 0" xyz="0.139342 -0.03 0.003053"/>
    <parent link="link_1_1"/>
    <child link="link_2_1"/>
    <axis xyz="-0.0 -1.0 0.0"/>
    <limit effort="100" lower="-0.349066" upper="0.349066" velocity="100"/>
  </joint>
</robot>
